Workbook

Sheet Dashboard
AB1: 0
B2: 📊 Project Tracker — Management Dashboard | AB2: =IF('Project Tracker'!D2="","",IF(COUNTIF('Project Tracker'!$D$2:D2,'Project Tracker'!D2)=1,MAX($AB$1:AB1)+1,"")) -> 1
B3: Live view of all projects — updates automatically as rows are added, edited, or removed in the Project Tracker sheet. | AB3: =IF('Project Tracker'!D3="","",IF(COUNTIF('Project Tracker'!$D$2:D3,'Project Tracker'!D3)=1,MAX($AB$1:AB2)+1,"")) -> 2
AB4: =IF('Project Tracker'!D4="","",IF(COUNTIF('Project Tracker'!$D$2:D4,'Project Tracker'!D4)=1,MAX($AB$1:AB3)+1,""))
AB5: =IF('Project Tracker'!D7="","",IF(COUNTIF('Project Tracker'!$D$2:D7,'Project Tracker'!D7)=1,MAX($AB$1:AB4)+1,""))
B6: 📁 TOTAL PROJECTS | E6: ✔ COMPLETED | H6: ⏳ IN PROGRESS | K6: ⏸ ON HOLD | N6: ○ NOT STARTED | AB6: =IF('Project Tracker'!D8="","",IF(COUNTIF('Project Tracker'!$D$2:D8,'Project Tracker'!D8)=1,MAX($AB$1:AB5)+1,""))
B7: =COUNTA(ProjectTracker[Client Name]) -> 339 | E7: =COUNTIF(ProjectTracker[Project Status],"Completed") -> 149 | H7: =COUNTIF(ProjectTracker[Project Status],"In Progress") -> 174 | K7: =COUNTIF(ProjectTracker[Project Status],"Hold") -> 7 | N7: =COUNTIF(ProjectTracker[Project Status],"Not Started") -> 9 | AB7: =IF('Project Tracker'!D9="","",IF(COUNTIF('Project Tracker'!$D$2:D9,'Project Tracker'!D9)=1,MAX($AB$1:AB6)+1,"")) -> 3
AB8: =IF('Project Tracker'!D10="","",IF(COUNTIF('Project Tracker'!$D$2:D10,'Project Tracker'!D10)=1,MAX($AB$1:AB7)+1,"")) -> 4
AB9: =IF('Project Tracker'!D11="","",IF(COUNTIF('Project Tracker'!$D$2:D11,'Project Tracker'!D11)=1,MAX($AB$1:AB8)+1,"")) -> 5
AB10: =IF('Project Tracker'!D12="","",IF(COUNTIF('Project Tracker'!$D$2:D12,'Project Tracker'!D12)=1,MAX($AB$1:AB9)+1,""))
B11: 📋 Auditor-wise Project Summary | AB11: =IF('Project Tracker'!D13="","",IF(COUNTIF('Project Tracker'!$D$2:D13,'Project Tracker'!D13)=1,MAX($AB$1:AB10)+1,""))
B12: The auditor list below is generated automatically from the Project Tracker sheet. Add, rename, or remove auditors there — this table (and the space reserved below it) updates on its own. | AB12: =IF('Project Tracker'!D14="","",IF(COUNTIF('Project Tracker'!$D$2:D14,'Project Tracker'!D14)=1,MAX($AB$1:AB11)+1,""))
AB13: =IF('Project Tracker'!D15="","",IF(COUNTIF('Project Tracker'!$D$2:D326,'Project Tracker'!D15)=1,MAX($AB$1:AB12)+1,""))
B14: 👤 Auditor | C14: ⚪ Not Started | D14: 🔵 In Progress | E14: 🟠 Hold | F14: 🟢 Completed | G14: Σ Total Projects | AB14: =IF('Project Tracker'!D16="","",IF(COUNTIF('Project Tracker'!$D$2:D16,'Project Tracker'!D16)=1,MAX($AB$1:AB13)+1,""))
B15: =IFERROR(INDEX('Project Tracker'!$D$2:$D$5040,MATCH(1,$AB$2:$AB$5000,0)),"") -> Dimple | C15: =IF($B15="","",COUNTIFS(ProjectTracker[Auditor],$B15,ProjectTracker[Project Status],"Not Started")) -> 0 | D15: =IF($B15="","",COUNTIFS(ProjectTracker[Auditor],$B15,ProjectTracker[Project Status],"In Progress")) -> 4 | E15: =IF($B15="","",COUNTIFS(ProjectTracker[Auditor],$B15,ProjectTracker[Project Status],"Hold")) -> 1 | F15: =IF($B15="","",COUNTIFS(ProjectTracker[Auditor],$B15,ProjectTracker[Project Status],"Completed")) -> 19 | G15: =IF($B15="","",SUM(C15:F15)) -> 24 | AB15: =IF('Project Tracker'!D17="","",IF(COUNTIF('Project Tracker'!$D$2:D17,'Project Tracker'!D17)=1,MAX($AB$1:AB14)+1,"")) -> 6
B16: =IFERROR(INDEX('Project Tracker'!$D$2:$D$5040,MATCH(2,$AB$2:$AB$5000,0)),"") -> Gautam Patidar | C16: =IF($B16="","",COUNTIFS(ProjectTracker[Auditor],$B16,ProjectTracker[Project Status],"Not Started")) -> 0 | D16: =IF($B16="","",COUNTIFS(ProjectTracker[Auditor],$B16,ProjectTracker[Project Status],"In Progress")) -> 6 | E16: =IF($B16="","",COUNTIFS(ProjectTracker[Auditor],$B16,ProjectTracker[Project Status],"Hold")) -> 0 | F16: =IF($B16="","",COUNTIFS(ProjectTracker[Auditor],$B16,ProjectTracker[Project Status],"Completed")) -> 2 | G16: =IF($B16="","",SUM(C16:F16)) -> 8 | AB16: =IF('Project Tracker'!D18="","",IF(COUNTIF('Project Tracker'!$D$2:D18,'Project Tracker'!D18)=1,MAX($AB$1:AB15)+1,""))
B17: =IFERROR(INDEX('Project Tracker'!$D$2:$D$5040,MATCH(3,$AB$2:$AB$5000,0)),"") -> Gautam Patidar | C17: =IF($B17="","",COUNTIFS(ProjectTracker[Auditor],$B17,ProjectTracker[Project Status],"Not Started")) -> 0 | D17: =IF($B17="","",COUNTIFS(ProjectTracker[Auditor],$B17,ProjectTracker[Project Status],"In Progress")) -> 6 | E17: =IF($B17="","",COUNTIFS(ProjectTracker[Auditor],$B17,ProjectTracker[Project Status],"Hold")) -> 0 | F17: =IF($B17="","",COUNTIFS(ProjectTracker[Auditor],$B17,ProjectTracker[Project Status],"Completed")) -> 2 | G17: =IF($B17="","",SUM(C17:F17)) -> 8 | AB17: =IF('Project Tracker'!D19="","",IF(COUNTIF('Project Tracker'!$D$2:D19,'Project Tracker'!D19)=1,MAX($AB$1:AB16)+1,""))
B18: =IFERROR(INDEX('Project Tracker'!$D$2:$D$5040,MATCH(4,$AB$2:$AB$5000,0)),"") -> Gautam Patidar | C18: =IF($B18="","",COUNTIFS(ProjectTracker[Auditor],$B18,ProjectTracker[Project Status],"Not Started")) -> 0 | D18: =IF($B18="","",COUNTIFS(ProjectTracker[Auditor],$B18,ProjectTracker[Project Status],"In Progress")) -> 6 | E18: =IF($B18="","",COUNTIFS(ProjectTracker[Auditor],$B18,ProjectTracker[Project Status],"Hold")) -> 0 | F18: =IF($B18="","",COUNTIFS(ProjectTracker[Auditor],$B18,ProjectTracker[Project Status],"Completed")) -> 2 | G18: =IF($B18="","",SUM(C18:F18)) -> 8 | AB18: =IF('Project Tracker'!D20="","",IF(COUNTIF('Project Tracker'!$D$2:D20,'Project Tracker'!D20)=1,MAX($AB$1:AB17)+1,"")) -> 7
B19: =IFERROR(INDEX('Project Tracker'!$D$2:$D$5040,MATCH(5,$AB$2:$AB$5000,0)),"") -> Akash | C19: =IF($B19="","",COUNTIFS(ProjectTracker[Auditor],$B19,ProjectTracker[Project Status],"Not Started")) -> 0 | D19: =IF($B19="","",COUNTIFS(ProjectTracker[Auditor],$B19,ProjectTracker[Project Status],"In Progress")) -> 12 | E19: =IF($B19="","",COUNTIFS(ProjectTracker[Auditor],$B19,ProjectTracker[Project Status],"Hold")) -> 0 | F19: =IF($B19="","",COUNTIFS(ProjectTracker[Auditor],$B19,ProjectTracker[Project Status],"Completed")) -> 4 | G19: =IF($B19="","",SUM(C19:F19)) -> 16 | AB19: =IF('Project Tracker'!D21="","",IF(COUNTIF('Project Tracker'!$D$2:D21,'Project Tracker'!D21)=1,MAX($AB$1:AB18)+1,""))
B20: =IFERROR(INDEX('Project Tracker'!$D$2:$D$5040,MATCH(6,$AB$2:$AB$5000,0)),"") -> Jayneel | C20: =IF($B20="","",COUNTIFS(ProjectTracker[Auditor],$B20,ProjectTracker[Project Status],"Not Started")) -> 0 | D20: =IF($B20="","",COUNTIFS(ProjectTracker[Auditor],$B20,ProjectTracker[Project Status],"In Progress")) -> 9 | E20: =IF($B20="","",COUNTIFS(ProjectTracker[Auditor],$B20,ProjectTracker[Project Status],"Hold")) -> 0 | F20: =IF($B20="","",COUNTIFS(ProjectTracker[Auditor],$B20,ProjectTracker[Project Status],"Completed")) -> 0 | G20: =IF($B20="","",SUM(C20:F20)) -> 9 | AB20: =IF('Project Tracker'!D22="","",IF(COUNTIF('Project Tracker'!$D$2:D22,'Project Tracker'!D22)=1,MAX($AB$1:AB19)+1,""))
B21: =IFERROR(INDEX('Project Tracker'!$D$2:$D$5040,MATCH(7,$AB$2:$AB$5000,0)),"") -> Anushree | C21: =IF($B21="","",COUNTIFS(ProjectTracker[Auditor],$B21,ProjectTracker[Project Status],"Not Started")) -> 0 | D21: =IF($B21="","",COUNTIFS(ProjectTracker[Auditor],$B21,ProjectTracker[Project Status],"In Progress")) -> 4 | E21: =IF($B21="","",COUNTIFS(ProjectTracker[Auditor],$B21,ProjectTracker[Project Status],"Hold")) -> 0 | F21: =IF($B21="","",COUNTIFS(ProjectTracker[Auditor],$B21,ProjectTracker[Project Status],"Completed")) -> 9 | G21: =IF($B21="","",SUM(C21:F21)) -> 13 | AB21: =IF('Project Tracker'!D23="","",IF(COUNTIF('Project Tracker'!$D$2:D23,'Project Tracker'!D23)=1,MAX($AB$1:AB20)+1,""))
B22: =IFERROR(INDEX('Project Tracker'!$D$2:$D$5040,MATCH(8,$AB$2:$AB$5000,0)),"") -> Pratham | C22: =IF($B22="","",COUNTIFS(ProjectTracker[Auditor],$B22,ProjectTracker[Project Status],"Not Started")) -> 0 | D22: =IF($B22="","",COUNTIFS(ProjectTracker[Auditor],$B22,ProjectTracker[Project Status],"In Progress")) -> 3 | E22: =IF($B22="","",COUNTIFS(ProjectTracker[Auditor],$B22,ProjectTracker[Project Status],"Hold")) -> 1 | F22: =IF($B22="","",COUNTIFS(ProjectTracker[Auditor],$B22,ProjectTracker[Project Status],"Completed")) -> 15 | G22: =IF($B22="","",SUM(C22:F22)) -> 19 | AB22: =IF('Project Tracker'!D24="","",IF(COUNTIF('Project Tracker'!$D$2:D24,'Project Tracker'!D24)=1,MAX($AB$1:AB21)+1,""))
B23: =IFERROR(INDEX('Project Tracker'!$D$2:$D$5040,MATCH(9,$AB$2:$AB$5000,0)),"") -> Gautam Patidar | C23: =IF($B23="","",COUNTIFS(ProjectTracker[Auditor],$B23,ProjectTracker[Project Status],"Not Started")) -> 0 | D23: =IF($B23="","",COUNTIFS(ProjectTracker[Auditor],$B23,ProjectTracker[Project Status],"In Progress")) -> 6 | E23: =IF($B23="","",COUNTIFS(ProjectTracker[Auditor],$B23,ProjectTracker[Project Status],"Hold")) -> 0 | F23: =IF($B23="","",COUNTIFS(ProjectTracker[Auditor],$B23,ProjectTracker[Project Status],"Completed")) -> 2 | G23: =IF($B23="","",SUM(C23:F23)) -> 8 | AB23: =IF('Project Tracker'!D25="","",IF(COUNTIF('Project Tracker'!$D$2:D25,'Project Tracker'!D25)=1,MAX($AB$1:AB22)+1,""))
B24: =IFERROR(INDEX('Project Tracker'!$D$2:$D$5040,MATCH(10,$AB$2:$AB$5000,0)),"") -> Dimple | C24: =IF($B24="","",COUNTIFS(ProjectTracker[Auditor],$B24,ProjectTracker[Project Status],"Not Started")) -> 0 | D24: =IF($B24="","",COUNTIFS(ProjectTracker[Auditor],$B24,ProjectTracker[Project Status],"In Progress")) -> 4 | E24: =IF($B24="","",COUNTIFS(ProjectTracker[Auditor],$B24,ProjectTracker[Project Status],"Hold")) -> 1 | F24: =IF($B24="","",COUNTIFS(ProjectTracker[Auditor],$B24,ProjectTracker[Project Status],"Completed")) -> 19 | G24: =IF($B24="","",SUM(C24:F24)) -> 24 | AB24: =IF('Project Tracker'!D26="","",IF(COUNTIF('Project Tracker'!$D$2:D26,'Project Tracker'!D26)=1,MAX($AB$1:AB23)+1,""))
B25: =IFERROR(INDEX('Project Tracker'!$D$2:$D$5040,MATCH(11,$AB$2:$AB$5000,0)),"") -> Jayraj | C25: =IF($B25="","",COUNTIFS(ProjectTracker[Auditor],$B25,ProjectTracker[Project Status],"Not Started")) -> 0 | D25: =IF($B25="","",COUNTIFS(ProjectTracker[Auditor],$B25,ProjectTracker[Project Status],"In Progress")) -> 3 | E25: =IF($B25="","",COUNTIFS(ProjectTracker[Auditor],$B25,ProjectTracker[Project Status],"Hold")) -> 0 | F25: =IF($B25="","",COUNTIFS(ProjectTracker[Auditor],$B25,ProjectTracker[Project Status],"Completed")) -> 1 | G25: =IF($B25="","",SUM(C25:F25)) -> 4 | AB25: =IF('Project Tracker'!D27="","",IF(COUNTIF('Project Tracker'!$D$2:D27,'Project Tracker'!D27)=1,MAX($AB$1:AB24)+1,"")) -> 8
B26: =IFERROR(INDEX('Project Tracker'!$D$2:$D$5040,MATCH(12,$AB$2:$AB$5000,0)),"") -> Jayneel Chokshi | C26: =IF($B26="","",COUNTIFS(ProjectTracker[Auditor],$B26,ProjectTracker[Project Status],"Not Started")) -> 0 | D26: =IF($B26="","",COUNTIFS(ProjectTracker[Auditor],$B26,ProjectTracker[Project Status],"In Progress")) -> 3 | E26: =IF($B26="","",COUNTIFS(ProjectTracker[Auditor],$B26,ProjectTracker[Project Status],"Hold")) -> 0 | F26: =IF($B26="","",COUNTIFS(ProjectTracker[Auditor],$B26,ProjectTracker[Project Status],"Completed")) -> 8 | G26: =IF($B26="","",SUM(C26:F26)) -> 11 | AB26: =IF('Project Tracker'!D28="","",IF(COUNTIF('Project Tracker'!$D$2:D28,'Project Tracker'!D28)=1,MAX($AB$1:AB25)+1,"")) -> 9
B27: =IFERROR(INDEX('Project Tracker'!$D$2:$D$5040,MATCH(13,$AB$2:$AB$5000,0)),"") -> Gautam Patidar , Anushree pillai, Aditya katkar | C27: =IF($B27="","",COUNTIFS(ProjectTracker[Auditor],$B27,ProjectTracker[Project Status],"Not Started")) -> 0 | D27: =IF($B27="","",COUNTIFS(ProjectTracker[Auditor],$B27,ProjectTracker[Project Status],"In Progress")) -> 0 | E27: =IF($B27="","",COUNTIFS(ProjectTracker[Auditor],$B27,ProjectTracker[Project Status],"Hold")) -> 0 | F27: =IF($B27="","",COUNTIFS(ProjectTracker[Auditor],$B27,ProjectTracker[Project Status],"Completed")) -> 3 | G27: =IF($B27="","",SUM(C27:F27)) -> 3 | AB27: =IF('Project Tracker'!D29="","",IF(COUNTIF('Project Tracker'!$D$2:D29,'Project Tracker'!D29)=1,MAX($AB$1:AB26)+1,""))
B28: =IFERROR(INDEX('Project Tracker'!$D$2:$D$5040,MATCH(14,$AB$2:$AB$5000,0)),"") -> Jayraj | C28: =IF($B28="","",COUNTIFS(ProjectTracker[Auditor],$B28,ProjectTracker[Project Status],"Not Started")) -> 0 | D28: =IF($B28="","",COUNTIFS(ProjectTracker[Auditor],$B28,ProjectTracker[Project Status],"In Progress")) -> 3 | E28: =IF($B28="","",COUNTIFS(ProjectTracker[Auditor],$B28,ProjectTracker[Project Status],"Hold")) -> 0 | F28: =IF($B28="","",COUNTIFS(ProjectTracker[Auditor],$B28,ProjectTracker[Project Status],"Completed")) -> 1 | G28: =IF($B28="","",SUM(C28:F28)) -> 4 | AB28: =IF('Project Tracker'!D30="","",IF(COUNTIF('Project Tracker'!$D$2:D30,'Project Tracker'!D30)=1,MAX($AB$1:AB27)+1,""))
B29: =IFERROR(INDEX('Project Tracker'!$D$2:$D$5040,MATCH(15,$AB$2:$AB$5000,0)),"") -> Jayraj, Anushree | C29: =IF($B29="","",COUNTIFS(ProjectTracker[Auditor],$B29,ProjectTracker[Project Status],"Not Started")) -> 0 | D29: =IF($B29="","",COUNTIFS(ProjectTracker[Auditor],$B29,ProjectTracker[Project Status],"In Progress")) -> 4 | E29: =IF($B29="","",COUNTIFS(ProjectTracker[Auditor],$B29,ProjectTracker[Project Status],"Hold")) -> 0 | F29: =IF($B29="","",COUNTIFS(ProjectTracker[Auditor],$B29,ProjectTracker[Project Status],"Completed")) -> 0 | G29: =IF($B29="","",SUM(C29:F29)) -> 4 | AB29: =IF('Project Tracker'!D31="","",IF(COUNTIF('Project Tracker'!$D$2:D31,'Project Tracker'!D31)=1,MAX($AB$1:AB28)+1,"")) -> 10
B30: =IFERROR(INDEX('Project Tracker'!$D$2:$D$5040,MATCH(16,$AB$2:$AB$5000,0)),"") -> Gautam Patidar | C30: =IF($B30="","",COUNTIFS(ProjectTracker[Auditor],$B30,ProjectTracker[Project Status],"Not Started")) -> 0 | D30: =IF($B30="","",COUNTIFS(ProjectTracker[Auditor],$B30,ProjectTracker[Project Status],"In Progress")) -> 6 | E30: =IF($B30="","",COUNTIFS(ProjectTracker[Auditor],$B30,ProjectTracker[Project Status],"Hold")) -> 0 | F30: =IF($B30="","",COUNTIFS(ProjectTracker[Auditor],$B30,ProjectTracker[Project Status],"Completed")) -> 2 | G30: =IF($B30="","",SUM(C30:F30)) -> 8 | AB30: =IF('Project Tracker'!D32="","",IF(COUNTIF('Project Tracker'!$D$2:D32,'Project Tracker'!D32)=1,MAX($AB$1:AB29)+1,""))
B31: =IFERROR(INDEX('Project Tracker'!$D$2:$D$5040,MATCH(17,$AB$2:$AB$5000,0)),"") -> Kavish | C31: =IF($B31="","",COUNTIFS(ProjectTracker[Auditor],$B31,ProjectTracker[Project Status],"Not Started")) -> 0 | D31: =IF($B31="","",COUNTIFS(ProjectTracker[Auditor],$B31,ProjectTracker[Project Status],"In Progress")) -> 0 | E31: =IF($B31="","",COUNTIFS(ProjectTracker[Auditor],$B31,ProjectTracker[Project Status],"Hold")) -> 0 | F31: =IF($B31="","",COUNTIFS(ProjectTracker[Auditor],$B31,ProjectTracker[Project Status],"Completed")) -> 1 | G31: =IF($B31="","",SUM(C31:F31)) -> 1 | AB31: =IF('Project Tracker'!D33="","",IF(COUNTIF('Project Tracker'!$D$2:D33,'Project Tracker'!D33)=1,MAX($AB$1:AB30)+1,"")) -> 11
B32: =IFERROR(INDEX('Project Tracker'!$D$2:$D$5040,MATCH(18,$AB$2:$AB$5000,0)),"") -> Alphae | C32: =IF($B32="","",COUNTIFS(ProjectTracker[Auditor],$B32,ProjectTracker[Project Status],"Not Started")) -> 1 | D32: =IF($B32="","",COUNTIFS(ProjectTracker[Auditor],$B32,ProjectTracker[Project Status],"In Progress")) -> 10 | E32: =IF($B32="","",COUNTIFS(ProjectTracker[Auditor],$B32,ProjectTracker[Project Status],"Hold")) -> 1 | F32: =IF($B32="","",COUNTIFS(ProjectTracker[Auditor],$B32,ProjectTracker[Project Status],"Completed")) -> 6 | G32: =IF($B32="","",SUM(C32:F32)) -> 18 | AB32: =IF('Project Tracker'!D34="","",IF(COUNTIF('Project Tracker'!$D$2:D34,'Project Tracker'!D34)=1,MAX($AB$1:AB31)+1,""))
B33: =IFERROR(INDEX('Project Tracker'!$D$2:$D$5040,MATCH(19,$AB$2:$AB$5000,0)),"") -> Ashutosh, Anushree | C33: =IF($B33="","",COUNTIFS(ProjectTracker[Auditor],$B33,ProjectTracker[Project Status],"Not Started")) -> 0 | D33: =IF($B33="","",COUNTIFS(ProjectTracker[Auditor],$B33,ProjectTracker[Project Status],"In Progress")) -> 0 | E33: =IF($B33="","",COUNTIFS(ProjectTracker[Auditor],$B33,ProjectTracker[Project Status],"Hold")) -> 0 | F33: =IF($B33="","",COUNTIFS(ProjectTracker[Auditor],$B33,ProjectTracker[Project Status],"Completed")) -> 1 | G33: =IF($B33="","",SUM(C33:F33)) -> 1 | AB33: =IF('Project Tracker'!D35="","",IF(COUNTIF('Project Tracker'!$D$2:D35,'Project Tracker'!D35)=1,MAX($AB$1:AB32)+1,""))
B34: =IFERROR(INDEX('Project Tracker'!$D$2:$D$5040,MATCH(20,$AB$2:$AB$5000,0)),"") -> Pratham | C34: =IF($B34="","",COUNTIFS(ProjectTracker[Auditor],$B34,ProjectTracker[Project Status],"Not Started")) -> 0 | D34: =IF($B34="","",COUNTIFS(ProjectTracker[Auditor],$B34,ProjectTracker[Project Status],"In Progress")) -> 3 | E34: =IF($B34="","",COUNTIFS(ProjectTracker[Auditor],$B34,ProjectTracker[Project Status],"Hold")) -> 1 | F34: =IF($B34="","",COUNTIFS(ProjectTracker[Auditor],$B34,ProjectTracker[Project Status],"Completed")) -> 15 | G34: =IF($B34="","",SUM(C34:F34)) -> 19 | AB34: =IF('Project Tracker'!D36="","",IF(COUNTIF('Project Tracker'!$D$2:D36,'Project Tracker'!D36)=1,MAX($AB$1:AB33)+1,"")) -> 12
B35: =IFERROR(INDEX('Project Tracker'!$D$2:$D$5040,MATCH(21,$AB$2:$AB$5000,0)),"") -> Sagar | C35: =IF($B35="","",COUNTIFS(ProjectTracker[Auditor],$B35,ProjectTracker[Project Status],"Not Started")) -> 0 | D35: =IF($B35="","",COUNTIFS(ProjectTracker[Auditor],$B35,ProjectTracker[Project Status],"In Progress")) -> 0 | E35: =IF($B35="","",COUNTIFS(ProjectTracker[Auditor],$B35,ProjectTracker[Project Status],"Hold")) -> 0 | F35: =IF($B35="","",COUNTIFS(ProjectTracker[Auditor],$B35,ProjectTracker[Project Status],"Completed")) -> 1 | G35: =IF($B35="","",SUM(C35:F35)) -> 1 | AB35: =IF('Project Tracker'!D37="","",IF(COUNTIF('Project Tracker'!$D$2:D37,'Project Tracker'!D37)=1,MAX($AB$1:AB34)+1,""))
B36: =IFERROR(INDEX('Project Tracker'!$D$2:$D$5040,MATCH(22,$AB$2:$AB$5000,0)),"") -> Anushree | C36: =IF($B36="","",COUNTIFS(ProjectTracker[Auditor],$B36,ProjectTracker[Project Status],"Not Started")) -> 0 | D36: =IF($B36="","",COUNTIFS(ProjectTracker[Auditor],$B36,ProjectTracker[Project Status],"In Progress")) -> 4 | E36: =IF($B36="","",COUNTIFS(ProjectTracker[Auditor],$B36,ProjectTracker[Project Status],"Hold")) -> 0 | F36: =IF($B36="","",COUNTIFS(ProjectTracker[Auditor],$B36,ProjectTracker[Project Status],"Completed")) -> 9 | G36: =IF($B36="","",SUM(C36:F36)) -> 13 | AB36: =IF('Project Tracker'!D38="","",IF(COUNTIF('Project Tracker'!$D$2:D38,'Project Tracker'!D38)=1,MAX($AB$1:AB35)+1,""))
B37: =IFERROR(INDEX('Project Tracker'!$D$2:$D$5040,MATCH(23,$AB$2:$AB$5000,0)),"") -> Alphae | C37: =IF($B37="","",COUNTIFS(ProjectTracker[Auditor],$B37,ProjectTracker[Project Status],"Not Started")) -> 1 | D37: =IF($B37="","",COUNTIFS(ProjectTracker[Auditor],$B37,ProjectTracker[Project Status],"In Progress")) -> 10 | E37: =IF($B37="","",COUNTIFS(ProjectTracker[Auditor],$B37,ProjectTracker[Project Status],"Hold")) -> 1 | F37: =IF($B37="","",COUNTIFS(ProjectTracker[Auditor],$B37,ProjectTracker[Project Status],"Completed")) -> 6 | G37: =IF($B37="","",SUM(C37:F37)) -> 18 | AB37: =IF('Project Tracker'!D39="","",IF(COUNTIF('Project Tracker'!$D$2:D39,'Project Tracker'!D39)=1,MAX($AB$1:AB36)+1,""))
B38: =IFERROR(INDEX('Project Tracker'!$D$2:$D$5040,MATCH(24,$AB$2:$AB$5000,0)),"") -> Vineet, Purvi | C38: =IF($B38="","",COUNTIFS(ProjectTracker[Auditor],$B38,ProjectTracker[Project Status],"Not Started")) -> 0 | D38: =IF($B38="","",COUNTIFS(ProjectTracker[Auditor],$B38,ProjectTracker[Project Status],"In Progress")) -> 0 | E38: =IF($B38="","",COUNTIFS(ProjectTracker[Auditor],$B38,ProjectTracker[Project Status],"Hold")) -> 0 | F38: =IF($B38="","",COUNTIFS(ProjectTracker[Auditor],$B38,ProjectTracker[Project Status],"Completed")) -> 1 | G38: =IF($B38="","",SUM(C38:F38)) -> 1 | AB38: =IF('Project Tracker'!D40="","",IF(COUNTIF('Project Tracker'!$D$2:D40,'Project Tracker'!D40)=1,MAX($AB$1:AB37)+1,"")) -> 13
B39: =IFERROR(INDEX('Project Tracker'!$D$2:$D$5040,MATCH(25,$AB$2:$AB$5000,0)),"") -> Pratham | C39: =IF($B39="","",COUNTIFS(ProjectTracker[Auditor],$B39,ProjectTracker[Project Status],"Not Started")) -> 0 | D39: =IF($B39="","",COUNTIFS(ProjectTracker[Auditor],$B39,ProjectTracker[Project Status],"In Progress")) -> 3 | E39: =IF($B39="","",COUNTIFS(ProjectTracker[Auditor],$B39,ProjectTracker[Project Status],"Hold")) -> 1 | F39: =IF($B39="","",COUNTIFS(ProjectTracker[Auditor],$B39,ProjectTracker[Project Status],"Completed")) -> 15 | G39: =IF($B39="","",SUM(C39:F39)) -> 19 | AB39: =IF('Project Tracker'!D41="","",IF(COUNTIF('Project Tracker'!$D$2:D41,'Project Tracker'!D41)=1,MAX($AB$1:AB38)+1,""))
B40: =IFERROR(INDEX('Project Tracker'!$D$2:$D$5040,MATCH(26,$AB$2:$AB$5000,0)),"") -> Akash | C40: =IF($B40="","",COUNTIFS(ProjectTracker[Auditor],$B40,ProjectTracker[Project Status],"Not Started")) -> 0 | D40: =IF($B40="","",COUNTIFS(ProjectTracker[Auditor],$B40,ProjectTracker[Project Status],"In Progress")) -> 12 | E40: =IF($B40="","",COUNTIFS(ProjectTracker[Auditor],$B40,ProjectTracker[Project Status],"Hold")) -> 0 | F40: =IF($B40="","",COUNTIFS(ProjectTracker[Auditor],$B40,ProjectTracker[Project Status],"Completed")) -> 4 | G40: =IF($B40="","",SUM(C40:F40)) -> 16 | AB40: =IF('Project Tracker'!D42="","",IF(COUNTIF('Project Tracker'!$D$2:D42,'Project Tracker'!D42)=1,MAX($AB$1:AB39)+1,""))
...

Sheet Project Tracker
A1: SR No. | B1: Client Name | C1: Type of Audit | D1: Auditor | E1: Cert-IN ID | F1: Doc ID No. | G1: Project Status | H1: Category | I1: Description | J1: BD | K1: Created Date | L1: Initial Gap Assessment Report Release Date | M1: Metadata of Initial Gap Assessment Report | N1: Closure Report Release Date | O1: Metadata of Closure Report | P1: Payment Confirmation | Q1: Report Prepared By | R1: Report Reviewed By | S1: Remarks
A2: 1 | B2: Astral | C2: Assessment | D2: Dimple | G2: Completed | H2: Enterprise | K2: 46062 | P2: Yes
A3: 2 | B3: Adani Airport - NMIAL | C3: ISO 27001 | D3: Gautam Patidar | G3: In Progress | H3: Enterprise | K3: 46009 | P3: No
A4: 3 | B4: Adani Airport - Mangalore | C4: ISO 27001 | D4: Gautam Patidar | G4: In Progress | H4: Enterprise | K4: 46009 | P4: No
A5: 4 | B5: Airport - TRV | C5: ISO 27001 | D5: Gautam Patidar | G5: In Progress | H5: Enterprise
A6: 5 | B6: Airport - Ahm | C6: ISO 27001 | D6: Gautam Patidar | G6: In Progress | H6: Enterprise
A7: 6 | B7: ETP Group - PCI SSS | C7: PCI SSS | D7: Gautam Patidar | G7: In Progress | H7: Enterprise | K7: 46001 | P7: No
A8: 7 | B8: ETP Group - PCI SSS | C8: PCI DSS | D8: Gautam Patidar | G8: Completed | H8: Enterprise | K8: 46001 | P8: Yes
A9: 8 | B9: Vidal Health | C9: SOC 2 | D9: Akash | G9: Completed | H9: Enterprise | K9: 45707 | P9: Yes
A10: 9 | B10: Adani Total Gas Limited and IOAGPL | C10: ISO 27001 | D10: Gautam Patidar, Anushree Pillai | G10: In Progress | H10: Enterprise | K10: 45965 | P10: No
A11: 10 | B11: Vigilhawk Labs | C11: ISO 9001 | D11: Jayneel | G11: In Progress | H11: Enterprise | K11: 45965 | P11: No
A12: 11 | B12: Vigilhawk Labs | C12: ISO 27001 | D12: Jayneel | G12: In Progress | H12: Enterprise | K12: 45965 | P12: No
A13: 12 | B13: Vigilhawk Labs | C13: SOC 2 - Type 2 | D13: Jayneel | G13: In Progress | H13: Enterprise | K13: 45965 | P13: No
A14: 13 | B14: Amzure Unified Services | C14: ISO 9001 | D14: Jayneel | G14: In Progress | H14: Enterprise | K14: 45965 | P14: No
A15: 14 | B15: Amzure Unified Services | C15: SOC 2 - Type 2 | D15: Jayneel | G15: In Progress | H15: Enterprise | K15: 45965 | P15: No
A16: 15 | B16: Amzure Unified Services | C16: ISO 27001 | D16: Jayneel | G16: In Progress | H16: Enterprise | K16: 45965 | P16: No
A17: 16 | B17: EZScript | C17: SOC 2 | D17: Anushree | G17: In Progress | H17: Enterprise | K17: 45896 | P17: No
A18: 17 | B18: EZScript | C18: HIPPA | D18: Anushree | G18: In Progress | H18: Enterprise | K18: 45896 | P18: No
... A30: 29 | B30: Octanom Tech Private Limited | C30: (Application Approval - NSE, BSE) | D30: Jayneel Chokshi | G30: Completed | H30: Enterprise | K30: 46104 | P30: Yes
A31: 30 | B31: HOCCO | C31: Maturity Assessment | D31: Jayraj | G31: In Progress | H31: Enterprise | J31: Jamin Doshi | K31: 46115 | P31: No
A32: 31 | B32: HOCCO | C32: ISO 27001 | D32: Jayraj | G32: In Progress | H32: Enterprise | J32: Jamin Doshi | K32: 46115 | P32: No
A33: 32 | B33: Inferenz Tech Private Limited - Surveillance Audit | C33: ISO 27001 | D33: Jayneel Chokshi, Akash Panchal | G33: Completed | H33: Enterprise | K33: 46118 | P33: Yes
A34: 33 | B34: JAPFA Comfeed India Pvt Ltd - Surveillance Audit | C34: ISO 27001 | D34: Jayneel Chokshi | G34: Completed | H34: Enterprise | J34: Mihir | K34: 46119 | P34: Yes
A35: 34 | B35: SandBox - ISO:27001 Renewal (Certification) (Sandbox's ISO 27001:2022 Re-certification Audit) | C35: ISO 27001 | D35: Dimple | G35: Completed | H35: Enterprise | J35: Ketan | K35: 46127 | P35: Yes
A36: 35 | B36: Multi Commodity Exchange Clearing Corporation Limited | C36: ISO 22301:2019 | D36: Gautam Patidar , Anushree pillai, Aditya katkar | G36: Completed | H36: Enterprise | J36: Shankhdeep | K36: 46127 | P36: Yes
A37: 36 | B37: Multi Commodity Exchange Clearing Corporation Limited | C37: ISO 27001 | D37: Gautam Patidar , Anushree pillai, Aditya katkar | G37: Completed | H37: Enterprise | J37: Shankhdeep | K37: 46127 | P37: Yes
A38: 37 | B38: Multi Commodity Exchange Clearing Corporation Limited | C38: ISO 9001 | D38: Gautam Patidar , Anushree pillai, Aditya katkar | G38: Completed | H38: Enterprise | J38: Shankhdeep | K38: 46127 | P38: Yes
A39: 38 | B39: Master Capital | C39: E-KYC | D39: Pratham | G39: In Progress | H39: Enterprise | K39: 46129 | P39: No
A40: 39 | B40: SR Algotech Private Limited - Algo Approval NSE | C40: Algo Approval Audit | D40: Tejas | G40: Not Started | H40: Enterprise | I40: Cancelled | J40: Shankhdeep | K40: 46133 | P40: No
A41: 40 | B41: SR Algotech Private Limited - Algo Approval BSE | C41: Algo Approval Audit | D41: Tejas | G41: Not Started | H41: Enterprise | I41: Cancelled | J41: Shankhdeep | K41: 46133 | P41: No
A42: 41 | B42: WISEOWL SECURITIES PRIVATE LIMITED (Finnhancer Solutions Private Limited) | C42: E-KYC | D42: Dimple | G42: Hold | H42: Enterprise | J42: Shankhdeep | K42: 46134 | P42: No
A43: 42 | B43: Societe Generale | C43: GRC - Activity | D43: Dimple | G43: Completed | H43: Enterprise | J43: Shankhdeep | K43: 46154 | P43: Yes
A44: 43 | B44: INFINITY CYBERSEC PTE LTD - SOC 2 | C44: SOC 2 - Type 2 | D44: Akash | G44: Completed | H44: Enterprise | K44: 46061 | P44: Yes
A45: 44 | B45: Sunidhi Securities & Finance Ltd - GRC ACTIVITY | C45: GRC - Activity | D45: Dimple | G45: Completed | H45: Enterprise | K45: 46099 | P45: Yes
A46: 45 | B46: Gretex Broking- IBT & STWT BSE F&O | C46: APPLICATION APPROVAL | D46: Dimple | G46: Completed | H46: Enterprise | K46: 45966 | P46: Yes
A47: 46 | B47: SUMANEL TECHNOLOGY VENTURES PVT LTD - SOC 2 | C47: SOC 2 - Type 2 | D47: Jayneel Chokshi | G47: Completed | H47: Enterprise | K47: Dec 2,2025 | P47: Yes
A48: 47 | B48: Chandrakala Broking Services Pvt. Ltd | C48: APPLICATION APPROVAL | D48: Dimple | G48: Completed | H48: Enterprise | K48: Mar 2,2025 | P48: Yes
A49: 48 | B49: Sunidhi Securities & Finance Ltd - Risk Assessment | C49: Risk Assessment | D49: Dimple | G49: Completed | H49: Enterprise | K49: Mar 18,2026 | P49: Yes
A50: 49 | B50: master trust - Application Approval | C50: APPLICATION APPROVAL | D50: Dimple | G50: Completed | H50: Enterprise | K50: 45908 | P50: Yes
A51: 50 | B51: Eureka Stock & Share Broking Services Limited | C51: APPLICATION APPROVAL | D51: Jayneel Chokshi | G51: Completed | H51: Enterprise | K51: 46063 | P51: Yes
...
